Workbook
Name Slicer_Education: #N/A
Name Slicer_Gender: #N/A
Name Slicer_Marital_Status: #N/A
Name Slicer_Performance_Rating: #N/A

Sheet Dashboard
H9: 10001 | I9: 10014
H10: 10001
H11: 0
H12: 0

Sheet HR_Data
A1: Employee_ID | B1: Employee_Code | C1: Age | D1: Gender | E1: City | F1: State | G1: Department | H1: Job_Role | I1: Education | J1: Marital_Status | K1: Monthly_Income | L1: Stock_Option_Level | M1: Years_At_Company | N1: Total_Working_Years | O1: Joining_Date | P1: Job_Satisfaction | Q1: Performance_Rating | R1: Overtime | S1: Attrition | T1: Training_Times_Last_Year | U1: Work_Life_Balance
A2: 10001 | B2: EMP10001 | C2: 38 | D2: Male | E2: Mumbai | F2: {=_xlfn.IFS( E2="Delhi","Delhi", E2="Ahmedabad","Gujarat", OR(E2="Mumbai",E2="Pune"),"Maharashtra", E2="Chennai","Tamil Nadu", E2="Hyderabad","Telangana", E2="Kolkata","West Bengal", E2="Bengaluru","Karnataka" )} -> Maharashtra | G2: Sales | H2: Sales Executive | I2: High School | J2: Single | K2: 83513 | L2: 1 | M2: 4 | N2: 5 | O2: 45376 | P2: 1 | Q2: 5 | R2: Yes | S2: No | T2: 1 | U2: 4
A3: 10002 | B3: EMP10002 | C3: 58 | D3: Female | E3: Chennai | F3: {=_xlfn.IFS( E3="Delhi","Delhi", E3="Ahmedabad","Gujarat", OR(E3="Mumbai",E3="Pune"),"Maharashtra", E3="Chennai","Tamil Nadu", E3="Hyderabad","Telangana", E3="Kolkata","West Bengal", E3="Bengaluru","Karnataka" )} -> Tamil Nadu | G3: Research & Development | H3: Laboratory Technician | I3: High School | J3: Single | K3: 26703 | L3: 3 | M3: 24 | N3: 26 | O3: 44371 | P3: 1 | Q3: 3 | R3: No | S3: No | T3: 6 | U3: 3
A4: 10003 | B4: EMP10003 | C4: 23 | D4: Female | E4: Chennai | F4: {=_xlfn.IFS( E4="Delhi","Delhi", E4="Ahmedabad","Gujarat", OR(E4="Mumbai",E4="Pune"),"Maharashtra", E4="Chennai","Tamil Nadu", E4="Hyderabad","Telangana", E4="Kolkata","West Bengal", E4="Bengaluru","Karnataka" )} -> Tamil Nadu | G4: IT | H4: Data Analyst | I4: Bachelor's | J4: Divorced | K4: 165568 | L4: 0 | M4: 0 | N4: 5 | O4: 41554 | P4: 1 | Q4: 2 | R4: No | S4: No | T4: 6 | U4: 3 | W4: =_xlfn.XLOOKUP(Dashboard!I9,HR_Data!A:A,HR_Data!H:H,"invalid",0) -> Finance Manager
A5: 10004 | B5: EMP10004 | C5: 27 | D5: Female | E5: Hyderabad | F5: {=_xlfn.IFS( E5="Delhi","Delhi", E5="Ahmedabad","Gujarat", OR(E5="Mumbai",E5="Pune"),"Maharashtra", E5="Chennai","Tamil Nadu", E5="Hyderabad","Telangana", E5="Kolkata","West Bengal", E5="Bengaluru","Karnataka" )} -> Telangana | G5: Sales | H5: Sales Executive | I5: High School | J5: Divorced | K5: 97869 | L5: 1 | M5: 7 | N5: 9 | O5: 42241 | P5: 2 | Q5: 2 | R5: No | S5: No | T5: 3 | U5: 4
A6: 10005 | B6: EMP10005 | C6: 56 | D6: Male | E6: Kolkata | F6: {=_xlfn.IFS( E6="Delhi","Delhi", E6="Ahmedabad","Gujarat", OR(E6="Mumbai",E6="Pune"),"Maharashtra", E6="Chennai","Tamil Nadu", E6="Hyderabad","Telangana", E6="Kolkata","West Bengal", E6="Bengaluru","Karnataka" )} -> West Bengal | G6: Human Resources | H6: Recruiter | I6: Master's | J6: Single | K6: 110008 | L6: 1 | M6: 24 | N6: 24 | O6: 42785 | P6: 3 | Q6: 2 | R6: No | S6: No | T6: 5 | U6: 4
A7: 10006 | B7: EMP10006 | C7: 50 | D7: Male | E7: Kolkata | F7: {=_xlfn.IFS( E7="Delhi","Delhi", E7="Ahmedabad","Gujarat", OR(E7="Mumbai",E7="Pune"),"Maharashtra", E7="Chennai","Tamil Nadu", E7="Hyderabad","Telangana", E7="Kolkata","West Bengal", E7="Bengaluru","Karnataka" )} -> West Bengal | G7: Finance | H7: Finance Manager | I7: Master's | J7: Single | K7: 94436 | L7: 1 | M7: 4 | N7: 7 | O7: 45324 | P7: 4 | Q7: 1 | R7: Yes | S7: No | T7: 6 | U7: 1
A8: 10007 | B8: EMP10007 | C8: 31 | D8: Female | E8: Mumbai | F8: {=_xlfn.IFS( E8="Delhi","Delhi", E8="Ahmedabad","Gujarat", OR(E8="Mumbai",E8="Pune"),"Maharashtra", E8="Chennai","Tamil Nadu", E8="Hyderabad","Telangana", E8="Kolkata","West Bengal", E8="Bengaluru","Karnataka" )} -> Maharashtra | G8: Sales | H8: Sales Executive | I8: High School | J8: Divorced | K8: 41653 | L8: 4 | M8: 6 | N8: 12 | O8: 44743 | P8: 3 | Q8: 3 | R8: No | S8: No | T8: 0 | U8: 3
A9: 10008 | B9: EMP10008 | C9: 50 | D9: Male | E9: Hyderabad | F9: {=_xlfn.IFS( E9="Delhi","Delhi", E9="Ahmedabad","Gujarat", OR(E9="Mumbai",E9="Pune"),"Maharashtra", E9="Chennai","Tamil Nadu", E9="Hyderabad","Telangana", E9="Kolkata","West Bengal", E9="Bengaluru","Karnataka" )} -> Telangana | G9: Finance | H9: Financial Analyst | I9: Bachelor's | J9: Single | K9: 94045 | L9: 2 | M9: 16 | N9: 18 | O9: 45067 | P9: 2 | Q9: 5 | R9: No | S9: No | T9: 6 | U9: 1
A10: 10009 | B10: EMP10009 | C10: 52 | D10: Male | E10: Pune | F10: {=_xlfn.IFS( E10="Delhi","Delhi", E10="Ahmedabad","Gujarat", OR(E10="Mumbai",E10="Pune"),"Maharashtra", E10="Chennai","Tamil Nadu", E10="Hyderabad","Telangana", E10="Kolkata","West Bengal", E10="Bengaluru","Karnataka" )} -> Maharashtra | G10: IT | H10: Data Analyst | I10: High School | J10: Divorced | K10: 54325 | L10: 3 | M10: 11 | N10: 15 | O10: 42870 | P10: 1 | Q10: 5 | R10: Yes | S10: No | T10: 6 | U10: 2
A11: 10010 | B11: EMP10010 | C11: 51 | D11: Male | E11: Bengaluru | F11: {=_xlfn.IFS( E11="Delhi","Delhi", E11="Ahmedabad","Gujarat", OR(E11="Mumbai",E11="Pune"),"Maharashtra", E11="Chennai","Tamil Nadu", E11="Hyderabad","Telangana", E11="Kolkata","West Bengal", E11="Bengaluru","Karnataka" )} -> Karnataka | G11: Research & Development | H11: Research Director | I11: Master's | J11: Married | K11: 94483 | L11: 2 | M11: 16 | N11: 22 | O11: 42644 | P11: 4 | Q11: 5 | R11: No | S11: No | T11: 3 | U11: 1
A12: 10011 | B12: EMP10011 | C12: 25 | D12: Female | E12: Bengaluru | F12: {=_xlfn.IFS( E12="Delhi","Delhi", E12="Ahmedabad","Gujarat", OR(E12="Mumbai",E12="Pune"),"Maharashtra", E12="Chennai","Tamil Nadu", E12="Hyderabad","Telangana", E12="Kolkata","West Bengal", E12="Bengaluru","Karnataka" )} -> Karnataka | G12: Research & Development | H12: Research Scientist | I12: High School | J12: Single | K12: 30514 | L12: 2 | M12: 3 | N12: 6 | O12: 40967 | P12: 1 | Q12: 5 | R12: Yes | S12: No | T12: 1 | U12: 3
A13: 10012 | B13: EMP10012 | C13: 55 | D13: Male | E13: Bengaluru | F13: {=_xlfn.IFS( E13="Delhi","Delhi", E13="Ahmedabad","Gujarat", OR(E13="Mumbai",E13="Pune"),"Maharashtra", E13="Chennai","Tamil Nadu", E13="Hyderabad","Telangana", E13="Kolkata","West Bengal", E13="Bengaluru","Karnataka" )} -> Karnataka | G13: Finance | H13: Financial Analyst | I13: High School | J13: Single | K13: 174695 | L13: 3 | M13: 18 | N13: 25 | O13: 42899 | P13: 3 | Q13: 4 | R13: No | S13: No | T13: 3 | U13: 4
A14: 10013 | B14: EMP10013 | C14: 27 | D14: Male | E14: Delhi | F14: {=_xlfn.IFS( E14="Delhi","Delhi", E14="Ahmedabad","Gujarat", OR(E14="Mumbai",E14="Pune"),"Maharashtra", E14="Chennai","Tamil Nadu", E14="Hyderabad","Telangana", E14="Kolkata","West Bengal", E14="Bengaluru","Karnataka" )} -> Delhi | G14: Sales | H14: Manager | I14: PhD | J14: Single | K14: 130544 | L14: 2 | M14: 5 | N14: 6 | O14: 42945 | P14: 4 | Q14: 2 | R14: Yes | S14: No | T14: 6 | U14: 1
A15: 10014 | B15: EMP10014 | C15: 27 | D15: Male | E15: Bengaluru | F15: {=_xlfn.IFS( E15="Delhi","Delhi", E15="Ahmedabad","Gujarat", OR(E15="Mumbai",E15="Pune"),"Maharashtra", E15="Chennai","Tamil Nadu", E15="Hyderabad","Telangana", E15="Kolkata","West Bengal", E15="Bengaluru","Karnataka" )} -> Karnataka | G15: Finance | H15: Finance Manager | I15: PhD | J15: Single | K15: 166711 | L15: 1 | M15: 0 | N15: 1 | O15: 42845 | P15: 4 | Q15: 1 | R15: Yes | S15: No | T15: 3 | U15: 3
A16: 10015 | B16: EMP10015 | C16: 48 | D16: Female | E16: Mumbai | F16: {=_xlfn.IFS( E16="Delhi","Delhi", E16="Ahmedabad","Gujarat", OR(E16="Mumbai",E16="Pune"),"Maharashtra", E16="Chennai","Tamil Nadu", E16="Hyderabad","Telangana", E16="Kolkata","West Bengal", E16="Bengaluru","Karnataka" )} -> Maharashtra | G16: Finance | H16: Accountant | I16: Master's | J16: Single | K16: 65579 | L16: 0 | M16: 6 | N16: 10 | O16: 42692 | P16: 4 | Q16: 5 | R16: No | S16: No | T16: 6 | U16: 2
... A1501: 11500 | B1501: EMP11500 | C1501: 29 | D1501: Male | E1501: Delhi | F1501: {=_xlfn.IFS( E1501="Delhi","Delhi", E1501="Ahmedabad","Gujarat", OR(E1501="Mumbai",E1501="Pune"),"Maharashtra", E1501="Chennai","Tamil Nadu", E1501="Hyderabad","Telangana", E1501="Kolkata","West Bengal", E1501="Bengaluru","Karnataka" )} -> Delhi | G1501: IT | H1501: IT Support Specialist | I1501: High School | J1501: Divorced | K1501: 101704 | L1501: 2 | M1501: 7 | N1501: 11 | O1501: 42088 | P1501: 3 | Q1501: 1 | R1501: No | S1501: No | T1501: 5 | U1501: 4

Sheet department wise emp
A1: Row Labels | B1: Count of Employee_ID
A2: Finance | B2: 321
A3: Human Resources | B3: 275
A4: IT | B4: 280
A5: Research & Development | B5: 308
A6: Sales | B6: 316

Sheet state wise emp
A3: Row Labels | B3: Count of Employee_ID
A4: Delhi | B4: 194 | C4: =A4 -> Delhi | D4: 194
A5: Gujarat | B5: 190 | C5: =A5 -> Gujarat | D5: 190
A6: Karnataka | B6: 187 | C6: =A6 -> Karnataka | D6: 187
A7: Maharashtra | B7: 379 | C7: =A7 -> Maharashtra | D7: 379
A8: Tamil Nadu | B8: 179 | C8: =A8 -> Tamil Nadu | D8: 179
A9: Telangana | B9: 183 | C9: =A9 -> Telangana | D9: 183
A10: West Bengal | B10: 188 | C10: =A10 -> West Bengal | D10: 188
A11: Grand Total | B11: 1500

Sheet job role wise emp
A3: Row Labels | B3: Count of Employee_ID
A4: Sales Executive | B4: 118
A5: Research Director | B5: 116
A6: Accountant | B6: 114
A7: Financial Analyst | B7: 113
A8: Sales Representative | B8: 111
A9: Software Engineer | B9: 101
A10: Research Scientist | B10: 96
A11: Laboratory Technician | B11: 96
A12: Data Analyst | B12: 95
A13: Finance Manager | B13: 94
A14: HR Executive | B14: 93
A15: Recruiter | B15: 91
... A18: IT Support Specialist | B18: 84

Sheet Basic
A1: Total Employee | B1: =COUNT(HR_Data!A:A) -> 1500
A2: Avg age of Emp | B2: =ROUND(AVERAGE(HR_Data!C:C),0) -> 39
A3: Highest monthly income | B3: =MAX(HR_Data!K:K) -> 179954
A4: Lowest monthly income | B4: =MIN(HR_Data!K:K) -> 25022
A5: Emp in IT | B5: =COUNTIF(HR_Data!G:G,"IT") -> 280
A6: Male emp | B6: =COUNTIF(HR_Data!D:D,"Male") -> 767
A7: Female emp | B7: =COUNTIF(HR_Data!D:D,"Female") -> 733
A8: Emp works in mumbai | B8: =COUNTIF(HR_Data!E:E,"Mumbai") -> 190
A9: total monthly income of all employees | B9: =SUM(HR_Data!K:K) -> 152335619
A10: average monthly income of employees in the Sales department | B10: =ROUND(AVERAGEIF(HR_Data!G:G,"Sales",HR_Data!K:K),0) -> 104905
A11: employees have more than 5 years of experience at the company | B11: =COUNTIF(HR_Data!M:M,">5") -> 913

Sheet med
A1: Age | B1: Gender | C1: City | D1: Department | E1: Job_Role | F1: Education | G1: Marital_Status | H1: Monthly_Income | J1: Age Group | K1: Income level
A2: 38 | B2: Male | C2: Mumbai | D2: Sales | E2: Sales Executive | F2: High School | G2: Single | H2: 83513 | J2: {=_xlfn.IFS(A2<30,"Young",AND(A2>=30,A2<=40),"Mid",A2>40,"Senior")} -> Mid | K2: {=_xlfn.IFS(H2<50000,"LOW",H2>50000,"MID",H2>100000,"High")} -> MID | L2: emp working over time | M2: =COUNTIF(HR_Data!R:R,"Yes") -> 435
A3: 58 | B3: Female | C3: Chennai | D3: Research & Development | E3: Laboratory Technician | F3: High School | G3: Single | H3: 26703 | J3: {=_xlfn.IFS(A3<30,"Young",AND(A3>=30,A3<=40),"Mid",A3>40,"Senior")} -> Senior | K3: {=_xlfn.IFS(H3<50000,"LOW",H3>50000,"MID",H3>100000,"High")} -> LOW | L3: percentage of employees have attrition = Yes? | M3: =COUNTIF(HR_Data!S:S,"Yes")/COUNTA(HR_Data!S:S) -> 0.12924717
A4: 23 | B4: Female | C4: Chennai | D4: IT | E4: Data Analyst | F4: Bachelor's | G4: Divorced | H4: 165568 | J4: {=_xlfn.IFS(A4<30,"Young",AND(A4>=30,A4<=40),"Mid",A4>40,"Senior")} -> Young | K4: {=_xlfn.IFS(H4<50000,"LOW",H4>50000,"MID",H4>100000,"High")} -> MID | L4: What is the average monthly income of employees who work overtime? | M4: =AVERAGEIF(HR_Data!R:R,"Yes",HR_Data!K:K) -> 98960.414
A5: 27 | B5: Female | C5: Hyderabad | D5: Sales | E5: Sales Executive | F5: High School | G5: Divorced | H5: 97869 | J5: {=_xlfn.IFS(A5<30,"Young",AND(A5>=30,A5<=40),"Mid",A5>40,"Senior")} -> Young | K5: {=_xlfn.IFS(H5<50000,"LOW",H5>50000,"MID",H5>100000,"High")} -> MID | L5: What is the total income generated by employees in the Finance department? | M5: =SUMIF(HR_Data!G:G,"Finance",HR_Data!K:K) -> 31046457
A6: 56 | B6: Male | C6: Kolkata | D6: Human Resources | E6: Recruiter | F6: Master's | G6: Single | H6: 110008 | J6: {=_xlfn.IFS(A6<30,"Young",AND(A6>=30,A6<=40),"Mid",A6>40,"Senior")} -> Senior | K6: {=_xlfn.IFS(H6<50000,"LOW",H6>50000,"MID",H6>100000,"High")} -> MID | L6: How many employees have a Performance Rating of 5?. | M6: =COUNTIF(HR_Data!Q:Q,"=5") -> 305
A7: 50 | B7: Male | C7: Kolkata | D7: Finance | E7: Finance Manager | F7: Master's | G7: Single | H7: 94436 | J7: {=_xlfn.IFS(A7<30,"Young",AND(A7>=30,A7<=40),"Mid",A7>40,"Senior")} -> Senior | K7: {=_xlfn.IFS(H7<50000,"LOW",H7>50000,"MID",H7>100000,"High")} -> MID | L7: How many employees have both:Overtime and Attrition | M7: =COUNTIFS(HR_Data!R:R,"Yes",HR_Data!S:S,"Yes") -> 92
A8: 31 | B8: Female | C8: Mumbai | D8: Sales | E8: Sales Executive | F8: High School | G8: Divorced | H8: 41653 | J8: {=_xlfn.IFS(A8<30,"Young",AND(A8>=30,A8<=40),"Mid",A8>40,"Senior")} -> Mid | K8: {=_xlfn.IFS(H8<50000,"LOW",H8>50000,"MID",H8>100000,"High")} -> LOW | L8: What is the average age of employees in the IT department? | M8: =AVERAGEIF(HR_Data!G:G,"IT",HR_Data!C:C) -> 39.542857
A9: 50 | B9: Male | C9: Hyderabad | D9: Finance | E9: Financial Analyst | F9: Bachelor's | G9: Single | H9: 94045 | J9: {=_xlfn.IFS(A9<30,"Young",AND(A9>=30,A9<=40),"Mid",A9>40,"Senior")} -> Senior | K9: {=_xlfn.IFS(H9<50000,"LOW",H9>50000,"MID",H9>100000,"High")} -> MID | L9: How many employees have Job Satisfaction ≥ 3 and Performance Rating ≥ 4? | M9: =COUNTIFS(HR_Data!P:P,">=3",HR_Data!Q:Q,">=4") -> 300
A10: 52 | B10: Male | C10: Pune | D10: IT | E10: Data Analyst | F10: High School | G10: Divorced | H10: 54325 | J10: {=_xlfn.IFS(A10<30,"Young",AND(A10>=30,A10<=40),"Mid",A10>40,"Senior")} -> Senior | K10: {=_xlfn.IFS(H10<50000,"LOW",H10>50000,"MID",H10>100000,"High")} -> MID
A11: 51 | B11: Male | C11: Bengaluru | D11: Research & Development | E11: Research Director | F11: Master's | G11: Married | H11: 94483 | J11: {=_xlfn.IFS(A11<30,"Young",AND(A11>=30,A11<=40),"Mid",A11>40,"Senior")} -> Senior | K11: {=_xlfn.IFS(H11<50000,"LOW",H11>50000,"MID",H11>100000,"High")} -> MID
A12: 25 | B12: Female | C12: Bengaluru | D12: Research & Development | E12: Research Scientist | F12: High School | G12: Single | H12: 30514 | J12: {=_xlfn.IFS(A12<30,"Young",AND(A12>=30,A12<=40),"Mid",A12>40,"Senior")} -> Young | K12: {=_xlfn.IFS(H12<50000,"LOW",H12>50000,"MID",H12>100000,"High")} -> LOW
A13: 55 | B13: Male | C13: Bengaluru | D13: Finance | E13: Financial Analyst | F13: High School | G13: Single | H13: 174695 | J13: {=_xlfn.IFS(A13<30,"Young",AND(A13>=30,A13<=40),"Mid",A13>40,"Senior")} -> Senior | K13: {=_xlfn.IFS(H13<50000,"LOW",H13>50000,"MID",H13>100000,"High")} -> MID | L13: Put employee id in M17 for fetching its info | M13: 10002
A14: 27 | B14: Male | C14: Delhi | D14: Sales | E14: Manager | F14: PhD | G14: Single | H14: 130544 | J14: {=_xlfn.IFS(A14<30,"Young",AND(A14>=30,A14<=40),"Mid",A14>40,"Senior")} -> Young | K14: {=_xlfn.IFS(H14<50000,"LOW",H14>50000,"MID",H14>100000,"High")} -> MID | M14: {=_xlfn.XLOOKUP(med!M13,HR_Data!A:A,HR_Data!A:U,0,0)} -> 10002 | N14: EMP10002 | O14: 58 | P14: Female | Q14: Chennai | R14: Tamil Nadu | S14: Research & Development | T14: Laboratory Technician | U14: High School | V14: Single | W14: 26703 | X14: 3 | Y14: 24 | Z14: 26 | AA14: 44371 | AB14: 1 | AC14: 3 | AD14: No | AE14: No | AF14: 6 | AG14: 3
A15: 27 | B15: Male | C15: Bengaluru | D15: Finance | E15: Finance Manager | F15: PhD | G15: Single | H15: 166711 | J15: {=_xlfn.IFS(A15<30,"Young",AND(A15>=30,A15<=40),"Mid",A15>40,"Senior")} -> Young | K15: {=_xlfn.IFS(H15<50000,"LOW",H15>50000,"MID",H15>100000,"High")} -> MID
A16: 48 | B16: Female | C16: Mumbai | D16: Finance | E16: Accountant | F16: Master's | G16: Single | H16: 65579 | J16: {=_xlfn.IFS(A16<30,"Young",AND(A16>=30,A16<=40),"Mid",A16>40,"Senior")} -> Senior | K16: {=_xlfn.IFS(H16<50000,"LOW",H16>50000,"MID",H16>100000,"High")} -> MID | M16: {=_xlfn.XLOOKUP(med!M13,HR_Data!A:A,HR_Data!A:H,0)} -> 10002 | N16: EMP10002 | O16: 58 | P16: Female | Q16: Chennai | R16: Tamil Nadu | S16: Research & Development | T16: Laboratory Technician
A17: 26 | B17: Male | C17: Bengaluru | D17: Sales | E17: Manager | F17: High School | G17: Divorced | H17: 42962 | J17: {=_xlfn.IFS(A17<30,"Young",AND(A17>=30,A17<=40),"Mid",A17>40,"Senior")} -> Young | K17: {=_xlfn.IFS(H17<50000,"LOW",H17>50000,"MID",H17>100000,"High")} -> LOW
A18: 41 | B18: Male | C18: Pune | D18: Human Resources | E18: HR Executive | F18: High School | G18: Married | H18: 94629 | J18: {=_xlfn.IFS(A18<30,"Young",AND(A18>=30,A18<=40),"Mid",A18>40,"Senior")} -> Senior | K18: {=_xlfn.IFS(H18<50000,"LOW",H18>50000,"MID",H18>100000,"High")} -> MID
A19: 29 | B19: Female | C19: Hyderabad | D19: IT | E19: Data Analyst | F19: High School | G19: Divorced | H19: 43033 | J19: {=_xlfn.IFS(A19<30,"Young",AND(A19>=30,A19<=40),"Mid",A19>40,"Senior")} -> Young | K19: {=_xlfn.IFS(H19<50000,"LOW",H19>50000,"MID",H19>100000,"High")} -> LOW | L19: Use FILTER to return all employees who:Work in IT and Have Performance Rating ≥ 4. | M19: {=_xlfn._xlws.FILTER(HR_Data!A:U,(HR_Data!G:G="IT")*(HR_Data!Q:Q>=4))} -> 10009 | N19: EMP10009 | O19: 52 | P19: Male | Q19: Pune | R19: Maharashtra | S19: IT | T19: Data Analyst | U19: High School | V19: Divorced | W19: 54325 | X19: 3 | Y19: 11 | Z19: 15 | AA19: 42870 | AB19: 1 | AC19: 5 | AD19: Yes | AE19: No | AF19: 6 | AG19: 2
A20: 56 | B20: Male | C20: Hyderabad | D20: Sales | E20: Sales Executive | F20: PhD | G20: Married | H20: 96394 | J20: {=_xlfn.IFS(A20<30,"Young",AND(A20>=30,A20<=40),"Mid",A20>40,"Senior")} -> Senior | K20: {=_xlfn.IFS(H20<50000,"LOW",H20>50000,"MID",H20>100000,"High")} -> MID | M20: 10029 | N20: EMP10029 | O20: 41 | P20: Female | Q20: Ahmedabad | R20: Gujarat | S20: IT | T20: IT Support Specialist | U20: PhD | V20: Married | W20: 157324 | X20: 1 | Y20: 13 | Z20: 21 | AA20: 44561 | AB20: 3 | AC20: 5 | AD20: No | AE20: No | AF20: 3 | AG20: 2
A21: 42 | B21: Male | C21: Delhi | D21: Sales | E21: Sales Executive | F21: High School | G21: Married | H21: 93670 | J21: {=_xlfn.IFS(A21<30,"Young",AND(A21>=30,A21<=40),"Mid",A21>40,"Senior")} -> Senior | K21: {=_xlfn.IFS(H21<50000,"LOW",H21>50000,"MID",H21>100000,"High")} -> MID | M21: 10038 | N21: EMP10038 | O21: 45 | P21: Female | Q21: Hyderabad | R21: Telangana | S21: IT | T21: IT Support Specialist | U21: Master's | V21: Married | W21: 32523 | X21: 4 | Y21: 15 | Z21: 20 | AA21: 42398 | AB21: 3 | AC21: 5 | AD21: No | AE21: No | AF21: 0 | AG21: 2
A22: 23 | B22: Female | C22: Kolkata | D22: Human Resources | E22: HR Manager | F22: Bachelor's | G22: Single | H22: 80070 | J22: {=_xlfn.IFS(A22<30,"Young",AND(A22>=30,A22<=40),"Mid",A22>40,"Senior")} -> Young | K22: {=_xlfn.IFS(H22<50000,"LOW",H22>50000,"MID",H22>100000,"High")} -> MID | M22: 10049 | N22: EMP10049 | O22: 50 | P22: Male | Q22: Mumbai | R22: Maharashtra | S22: IT | T22: Software Engineer | U22: PhD | V22: Married | W22: 107448 | X22: 0 | Y22: 8 | Z22: 13 | AA22: 41858 | AB22: 2 | AC22: 5 | AD22: No | AE22: No | AF22: 2 | AG22: 4
A23: 36 | B23: Female | C23: Ahmedabad | D23: Human Resources | E23: HR Manager | F23: Master's | G23: Married | H23: 66732 | J23: {=_xlfn.IFS(A23<30,"Young",AND(A23>=30,A23<=40),"Mid",A23>40,"Senior")} -> Mid | K23: {=_xlfn.IFS(H23<50000,"LOW",H23>50000,"MID",H23>100000,"High")} -> MID | M23: 10067 | N23: EMP10067 | O23: 25 | P23: Female | Q23: Mumbai | R23: Maharashtra | S23: IT | T23: Software Engineer | U23: Master's | V23: Married | W23: 142512 | X23: 0 | Y23: 5 | Z23: 7 | AA23: 41802 | AB23: 1 | AC23: 4 | AD23: No | AE23: No | AF23: 6 | AG23: 4
A24: 38 | B24: Male | C24: Chennai | D24: Finance | E24: Accountant | F24: High School | G24: Single | H24: 98170 | J24: {=_xlfn.IFS(A24<30,"Young",AND(A24>=30,A24<=40),"Mid",A24>40,"Senior")} -> Mid | K24: {=_xlfn.IFS(H24<50000,"LOW",H24>50000,"MID",H24>100000,"High")} -> MID | M24: 10078 | N24: EMP10078 | O24: 33 | P24: Female | Q24: Delhi | R24: Delhi | S24: IT | T24: IT Support Specialist | U24: High School | V24: Single | W24: 117038 | X24: 3 | Y24: 4 | Z24: 7 | AA24: 41751 | AB24: 4 | AC24: 5 | AD24: Yes | AE24: Yes | AF24: 6 | AG24: 4
A25: 48 | B25: Female | C25: Hyderabad | D25: Sales | E25: Manager | F25: High School | G25: Divorced | H25: 107228 | J25: {=_xlfn.IFS(A25<30,"Young",AND(A25>=30,A25<=40),"Mid",A25>40,"Senior")} -> Senior | K25: {=_xlfn.IFS(H25<50000,"LOW",H25>50000,"MID",H25>100000,"High")} -> MID | M25: 10085 | N25: EMP10085 | O25: 49 | P25: Male | Q25: Ahmedabad | R25: Gujarat | S25: IT | T25: Software Engineer | U25: Bachelor's | V25: Divorced | W25: 132704 | X25: 1 | Y25: 11 | Z25: 14 | AA25: 44547 | AB25: 3 | AC25: 4 | AD25: No | AE25: No | AF25: 6 | AG25: 2
A26: 25 | B26: Female | C26: Kolkata | D26: Human Resources | E26: HR Manager | F26: Master's | G26: Divorced | H26: 107291 | J26: {=_xlfn.IFS(A26<30,"Young",AND(A26>=30,A26<=40),"Mid",A26>40,"Senior")} -> Young | K26: {=_xlfn.IFS(H26<50000,"LOW",H26>50000,"MID",H26>100000,"High")} -> MID | M26: 10095 | N26: EMP10095 | O26: 55 | P26: Female | Q26: Kolkata | R26: West Bengal | S26: IT | T26: Software Engineer | U26: Bachelor's | V26: Divorced | W26: 109203 | X26: 3 | Y26: 3 | Z26: 4 | AA26: 43595 | AB26: 3 | AC26: 4 | AD26: No | AE26: No | AF26: 0 | AG26: 3
A27: 57 | B27: Female | C27: Chennai | D27: Research & Development | E27: Research Director | F27: PhD | G27: Married | H27: 131450 | J27: {=_xlfn.IFS(A27<30,"Young",AND(A27>=30,A27<=40),"Mid",A27>40,"Senior")} -> Senior | K27: {=_xlfn.IFS(H27<50000,"LOW",H27>50000,"MID",H27>100000,"High")} -> MID | M27: 10109 | N27: EMP10109 | O27: 28 | P27: Male | Q27: Delhi | R27: Delhi | S27: IT | T27: Data Analyst | U27: Bachelor's | V27: Divorced | W27: 50344 | X27: 4 | Y27: 6 | Z27: 10 | AA27: 43686 | AB27: 4 | AC27: 5 | AD27: No | AE27: No | AF27: 0 | AG27: 1
A28: 53 | B28: Female | C28: Mumbai | D28: Sales | E28: Sales Representative | F28: High School | G28: Single | H28: 49480 | J28: {=_xlfn.IFS(A28<30,"Young",AND(A28>=30,A28<=40),"Mid",A28>40,"Senior")} -> Senior | K28: {=_xlfn.IFS(H28<50000,"LOW",H28>50000,"MID",H28>100000,"High")} -> LOW | M28: 10135 | N28: EMP10135 | O28: 25 | P28: Male | Q28: Bengaluru | R28: Karnataka | S28: IT | T28: Software Engineer | U28: PhD | V28: Married | W28: 26673 | X28: 0 | Y28: 6 | Z28: 7 | AA28: 42804 | AB28: 4 | AC28: 4 | AD28: Yes | AE28: Yes | AF28: 0 | AG28: 1
A29: 46 | B29: Male | C29: Ahmedabad | D29: Finance | E29: Accountant | F29: High School | G29: Divorced | H29: 63684 | J29: {=_xlfn.IFS(A29<30,"Young",AND(A29>=30,A29<=40),"Mid",A29>40,"Senior")} -> Senior | K29: {=_xlfn.IFS(H29<50000,"LOW",H29>50000,"MID",H29>100000,"High")} -> MID | M29: 10156 | N29: EMP10156 | O29: 43 | P29: Male | Q29: Ahmedabad | R29: Gujarat | S29: IT | T29: Software Engineer | U29: PhD | V29: Divorced | W29: 152037 | X29: 3 | Y29: 4 | Z29: 7 | AA29: 44054 | AB29: 4 | AC29: 4 | AD29: No | AE29: No | AF29: 3 | AG29: 2
A30: 41 | B30: Female | C30: Ahmedabad | D30: IT | E30: IT Support Specialist | F30: PhD | G30: Married | H30: 157324 | J30: {=_xlfn.IFS(A30<30,"Young",AND(A30>=30,A30<=40),"Mid",A30>40,"Senior")} -> Senior | K30: {=_xlfn.IFS(H30<50000,"LOW",H30>50000,"MID",H30>100000,"High")} -> MID | M30: 10198 | N30: EMP10198 | O30: 30 | P30: Male | Q30: Bengaluru | R30: Karnataka | S30: IT | T30: Software Engineer | U30: High School | V30: Married | W30: 47467 | X30: 4 | Y30: 10 | Z30: 12 | AA30: 45344 | AB30: 4 | AC30: 5 | AD30: No | AE30: No | AF30: 5 | AG30: 4
A31: 25 | B31: Female | C31: Delhi | D31: Human Resources | E31: HR Manager | F31: Bachelor's | G31: Married | H31: 86471 | J31: {=_xlfn.IFS(A31<30,"Young",AND(A31>=30,A31<=40),"Mid",A31>40,"Senior")} -> Young | K31: {=_xlfn.IFS(H31<50000,"LOW",H31>50000,"MID",H31>100000,"High")} -> MID | M31: 10201 | N31: EMP10201 | O31: 21 | P31: Female | Q31: Pune | R31: Maharashtra | S31: IT | T31: Data Analyst | U31: High School | V31: Divorced | W31: 54496 | X31: 0 | Y31: 3 | Z31: 3 | AA31: 42123 | AB31: 3 | AC31: 5 | AD31: No | AE31: No | AF31: 2 | AG31: 4
... A121: 27 | B121: Male | C121: Ahmedabad | D121: Sales | E121: Sales Representative | F121: Master's | G121: Married | H121: 61860 | J121: {=_xlfn.IFS(A121<30,"Young",AND(A121>=30,A121<=40),"Mid",A121>40,"Senior")} -> Young | K121: {=_xlfn.IFS(H121<50000,"LOW",H121>50000,"MID",H121>100000,"High")} -> MID | M121: 11488 | N121: EMP11488 | O121: 43 | P121: Male | Q121: Kolkata | R121: West Bengal | S121: IT | T121: Data Analyst | U121: Master's | V121: Single | W121: 52370 | X121: 2 | Y121: 2 | Z121: 9 | AA121: 44996 | AB121: 2 | AC121: 4 | AD121: No | AE121: No | AF121: 5 | AG121: 4
A122: 28 | B122: Female | C122: Hyderabad | D122: Research & Development | E122: Research Scientist | F122: High School | G122: Divorced | H122: 105427 | J122: {=_xlfn.IFS(A122<30,"Young",AND(A122>=30,A122<=40),"Mid",A122>40,"Senior")} -> Young | K122: {=_xlfn.IFS(H122<50000,"LOW",H122>50000,"MID",H122>100000,"High")} -> MID
A123: 30 | B123: Female | C123: Bengaluru | D123: Research & Development | E123: Laboratory Technician | F123: Bachelor's | G123: Divorced | H123: 122943 | J123: {=_xlfn.IFS(A123<30,"Young",AND(A123>=30,A123<=40),"Mid",A123>40,"Senior")} -> Mid | K123: {=_xlfn.IFS(H123<50000,"LOW",H123>50000,"MID",H123>100000,"High")} -> MID
A124: 28 | B124: Male | C124: Ahmedabad | D124: Sales | E124: Manager | F124: High School | G124: Divorced | H124: 168562 | J124: {=_xlfn.IFS(A124<30,"Young",AND(A124>=30,A124<=40),"Mid",A124>40,"Senior")} -> Young | K124: {=_xlfn.IFS(H124<50000,"LOW",H124>50000,"MID",H124>100000,"High")} -> MID
A125: 29 | B125: Female | C125: Mumbai | D125: Sales | E125: Sales Representative | F125: PhD | G125: Married | H125: 144746 | J125: {=_xlfn.IFS(A125<30,"Young",AND(A125>=30,A125<=40),"Mid",A125>40,"Senior")} -> Young | K125: {=_xlfn.IFS(H125<50000,"LOW",H125>50000,"MID",H125>100000,"High")} -> MID
A126: 25 | B126: Male | C126: Kolkata | D126: Finance | E126: Accountant | F126: Master's | G126: Married | H126: 43092 | J126: {=_xlfn.IFS(A126<30,"Young",AND(A126>=30,A126<=40),"Mid",A126>40,"Senior")} -> Young | K126: {=_xlfn.IFS(H126<50000,"LOW",H126>50000,"MID",H126>100000,"High")} -> LOW
A127: 32 | B127: Female | C127: Ahmedabad | D127: Human Resources | E127: HR Executive | F127: PhD | G127: Divorced | H127: 163632 | J127: {=_xlfn.IFS(A127<30,"Young",AND(A127>=30,A127<=40),"Mid",A127>40,"Senior")} -> Mid | K127: {=_xlfn.IFS(H127<50000,"LOW",H127>50000,"MID",H127>100000,"High")} -> MID
A128: 33 | B128: Male | C128: Mumbai | D128: Research & Development | E128: Laboratory Technician | F128: PhD | G128: Divorced | H128: 33445 | J128: {=_xlfn.IFS(A128<30,"Young",AND(A128>=30,A128<=40),"Mid",A128>40,"Senior")} -> Mid | K128: {=_xlfn.IFS(H128<50000,"LOW",H128>50000,"MID",H128>100000,"High")} -> LOW
A129: 34 | B129: Male | C129: Chennai | D129: Research & Development | E129: Research Director | F129: Master's | G129: Single | H129: 61735 | J129: {=_xlfn.IFS(A129<30,"Young",AND(A129>=30,A129<=40),"Mid",A129>40,"Senior")} -> Mid | K129: {=_xlfn.IFS(H129<50000,"LOW",H129>50000,"MID",H129>100000,"High")} -> MID
...

Sheet pivot
A3: Row Labels | B3: Count of Employee_ID | C3: Count of Attrition | D3: Average of Monthly_Income | E3: Average of Age
A4: Finance | B4: 321 | C4: 321 | D4: 96717.935 | E4: 39.065421
A5: Human Resources | B5: 275 | C5: 275 | D5: 102622.92 | E5: 40.472727
A6: IT | B6: 280 | C6: 280 | D6: 101140.94 | E6: 39.542857
A7: Research & Development | B7: 308 | C7: 308 | D7: 102592.51 | E7: 39.058442
A8: Sales | B8: 316 | C8: 316 | D8: 104904.75 | E8: 39.306962
A9: Grand Total | B9: 1500 | C9: 1500 | D9: 101557.08 | E9: 39.462

Sheet exp in company 
A3: Row Labels | B3: Count of Employee_ID | C3: Years in the company | D3: Count of emp
A4: 0 | B4: 100 | C4: =A4 -> 0 | D4: =GETPIVOTDATA("Employee_ID",$A$3,"Years_At_Company",0) -> 100
A5: 1 | B5: 108 | C5: =A5 -> 1 | D5: =GETPIVOTDATA("Employee_ID",$A$5,"Years_At_Company",A5) -> 108
A6: 2 | B6: 111 | C6: =A6 -> 2 | D6: =GETPIVOTDATA("Employee_ID",$A$5,"Years_At_Company",A6) -> 111
A7: 3 | B7: 85 | C7: =A7 -> 3 | D7: =GETPIVOTDATA("Employee_ID",$A$5,"Years_At_Company",A7) -> 85
A8: 4 | B8: 93 | C8: =A8 -> 4 | D8: =GETPIVOTDATA("Employee_ID",$A$5,"Years_At_Company",A8) -> 93
A9: 5 | B9: 90 | C9: =A9 -> 5 | D9: =GETPIVOTDATA("Employee_ID",$A$5,"Years_At_Company",A9) -> 90
A10: 6 | B10: 86 | C10: =A10 -> 6 | D10: =GETPIVOTDATA("Employee_ID",$A$5,"Years_At_Company",A10) -> 86
A11: 7 | B11: 79 | C11: =A11 -> 7 | D11: =GETPIVOTDATA("Employee_ID",$A$5,"Years_At_Company",A11) -> 79
A12: 8 | B12: 70 | C12: =A12 -> 8 | D12: =GETPIVOTDATA("Employee_ID",$A$5,"Years_At_Company",A12) -> 70
A13: 9 | B13: 61 | C13: =A13 -> 9 | D13: =GETPIVOTDATA("Employee_ID",$A$5,"Years_At_Company",A13) -> 61
A14: 10 | B14: 69 | C14: =A14 -> 10 | D14: =GETPIVOTDATA("Employee_ID",$A$5,"Years_At_Company",A14) -> 69
A15: 11 | B15: 52 | C15: =A15 -> 11 | D15: =GETPIVOTDATA("Employee_ID",$A$5,"Years_At_Company",A15) -> 52
A16: 12 | B16: 55 | C16: =A16 -> 12 | D16: =GETPIVOTDATA("Employee_ID",$A$5,"Years_At_Company",A16) -> 55
... A29: 25 | B29: 25 | C29: =A29 -> 25 | D29: =GETPIVOTDATA("Employee_ID",$A$5,"Years_At_Company",A29) -> 25
